Workbook
Name formulaPerformanceSheet: 'Formula_Sheet'!$N$6:$N$35

Sheet Summary
D2: Lighthouse Report
B3: Websites | D3: Performance
B4: Page | C4: Device | D4: With Cache | E4: Without Cache | G4: Analysis Results
D6: Oct 19, 2025, 11:09:10 AM | E6: Oct 19, 2025, 11:09:10 AM | G6: =IF(OR(ISBLANK(D6),ISBLANK(E6),TEXT(D6,"mmmm d, yyyy, h:mm:ss am/pm")<>D6,TEXT(E6,"mmmm d, yyyy, h:mm:ss am/pm")<>E6), "Kindly add Analysis Timestamp!", IF(OR(Formula_Sheet!K6=0,Formula_Sheet!N6=0), "Fill performance score for Home page first!", "The best recorded performance score was in " & Formula_Sheet!J6 & " devices " & Formula_Sheet!J7 & ", at " & Formula_Sheet!K6 & CHAR(10) & "The worst recorded performance score was in " & Formula_Sheet!M6 & " devices " & Formula_Sheet!M7 & ", at " & Formula_Sheet!N6 & CHAR(10) & "Refer to " & Formula_Sheet!B7 & " tab for the best and worst insight, links for full diagnostic readings and recommendations for improvement." )) -> Kindly add Analysis Timestamp!
B7: 01_First Link | C7: Desktop | D7: 96 | E7: 97
C8: Mobile | D8: 44 | E8: 43
D10: Oct 19, 2025, 11:09:45 AM | E10: Oct 19, 2025, 11:09:45 AM | G10: =IF(OR(ISBLANK(D10),ISBLANK(E10),TEXT(D10,"mmmm d, yyyy, h:mm:ss am/pm")<>D10,TEXT(E10,"mmmm d, yyyy, h:mm:ss am/pm")<>E10), "Kindly add Analysis Timestamp!", IF(OR(Formula_Sheet!K10=0,Formula_Sheet!N10=0), "Fill performance score for Home page first!", "The best recorded performance score was in " & Formula_Sheet!J10 & " devices " & Formula_Sheet!J11 & ", at " & Formula_Sheet!K10 & CHAR(10) & "The worst recorded performance score was in " & Formula_Sheet!M10 & " devices " & Formula_Sheet!M11 & ", at " & Formula_Sheet!N10 & CHAR(10) & "Refer to " & Formula_Sheet!B11 & " tab for the best and worst insight, links for full diagnostic readings and recommendations for improvement." )) -> Kindly add Analysis Timestamp!
B11: 02_Second Link | C11: Desktop | D11: 69 | E11: 60
C12: Mobile | D12: 54 | E12: 52
D14: Oct 19, 2025, 11:12:02 AM | E14: Oct 19, 2025, 11:12:02 AM | G14: =IF(OR(ISBLANK(D14),ISBLANK(E14),TEXT(D14,"mmmm d, yyyy, h:mm:ss am/pm")<>D14,TEXT(E14,"mmmm d, yyyy, h:mm:ss am/pm")<>E14), "Kindly add Analysis Timestamp!", IF(OR(Formula_Sheet!K14=0,Formula_Sheet!N14=0), "Fill performance score for Home page first!", "The best recorded performance score was in " & Formula_Sheet!J14 & " devices " & Formula_Sheet!J15 & ", at " & Formula_Sheet!K14 & CHAR(10) & "The worst recorded performance score was in " & Formula_Sheet!M14 & " devices " & Formula_Sheet!M15 & ", at " & Formula_Sheet!N14 & CHAR(10) & "Refer to " & Formula_Sheet!B15 & " tab for the best and worst insight, links for full diagnostic readings and recommendations for improvement." )) -> Kindly add Analysis Timestamp!
B15: 03_Third Link | C15: Desktop | D15: 94 | E15: 93
C16: Mobile | D16: 44 | E16: 43
D18: Oct 19, 2025, 11:12:37 AM | E18: Oct 19, 2025, 11:12:37 AM | G18: =IF(OR(ISBLANK(D18),ISBLANK(E18),TEXT(D18,"mmmm d, yyyy, h:mm:ss am/pm")<>D18,TEXT(E18,"mmmm d, yyyy, h:mm:ss am/pm")<>E18), "Kindly add Analysis Timestamp!", IF(OR(Formula_Sheet!K18=0,Formula_Sheet!N18=0), "Fill performance score for Home page first!", "The best recorded performance score was in " & Formula_Sheet!J18 & " devices " & Formula_Sheet!J19 & ", at " & Formula_Sheet!K18 & CHAR(10) & "The worst recorded performance score was in " & Formula_Sheet!M18 & " devices " & Formula_Sheet!M19 & ", at " & Formula_Sheet!N18 & CHAR(10) & "Refer to " & Formula_Sheet!B19 & " tab for the best and worst insight, links for full diagnostic readings and recommendations for improvement." )) -> Kindly add Analysis Timestamp!
B19: 04_Fourth Link | C19: Desktop | D19: 69 | E19: 71
C20: Mobile | D20: 59 | E20: 38
D22: Oct 19, 2025, 11:13:09 AM | E22: Oct 19, 2025, 11:13:09 AM | G22: =IF(OR(ISBLANK(D22),ISBLANK(E22),TEXT(D22,"mmmm d, yyyy, h:mm:ss am/pm")<>D22,TEXT(E22,"mmmm d, yyyy, h:mm:ss am/pm")<>E22), "Kindly add Analysis Timestamp!", IF(OR(Formula_Sheet!K22=0,Formula_Sheet!N22=0), "Fill performance score for Home page first!", "The best recorded performance score was in " & Formula_Sheet!J22 & " devices " & Formula_Sheet!J23 & ", at " & Formula_Sheet!K22 & CHAR(10) & "The worst recorded performance score was in " & Formula_Sheet!M22 & " devices " & Formula_Sheet!M23 & ", at " & Formula_Sheet!N22 & CHAR(10) & "Refer to " & Formula_Sheet!B23 & " tab for the best and worst insight, links for full diagnostic readings and recommendations for improvement." )) -> Kindly add Analysis Timestamp!
B23: 05_Fifth Link | C23: Desktop | D23: 54 | E23: 57
C24: Mobile | D24: 33 | E24: 33
D26: Oct 19, 2025, 11:15:49 AM | E26: Oct 19, 2025, 11:15:49 AM | G26: =IF(OR(ISBLANK(D26),ISBLANK(E26),TEXT(D26,"mmmm d, yyyy, h:mm:ss am/pm")<>D26,TEXT(E26,"mmmm d, yyyy, h:mm:ss am/pm")<>E26), "Kindly add Analysis Timestamp!", IF(OR(Formula_Sheet!K26=0,Formula_Sheet!N26=0), "Fill performance score for Home page first!", "The best recorded performance score was in " & Formula_Sheet!J26 & " devices " & Formula_Sheet!J27 & ", at " & Formula_Sheet!K26 & CHAR(10) & "The worst recorded performance score was in " & Formula_Sheet!M26 & " devices " & Formula_Sheet!M27 & ", at " & Formula_Sheet!N26 & CHAR(10) & "Refer to " & Formula_Sheet!B27 & " tab for the best and worst insight, links for full diagnostic readings and recommendations for improvement." )) -> Kindly add Analysis Timestamp!
B27: 06_Sixth Link | C27: Desktop | D27: 53 | E27: 57
C28: Mobile | D28: 33 | E28: 55
D30: Oct 19, 2025, 11:18:27 AM | E30: Oct 19, 2025, 11:18:27 AM | G30: =IF(OR(ISBLANK(D30),ISBLANK(E30),TEXT(D30,"mmmm d, yyyy, h:mm:ss am/pm")<>D30,TEXT(E30,"mmmm d, yyyy, h:mm:ss am/pm")<>E30), "Kindly add Analysis Timestamp!", IF(OR(Formula_Sheet!K30=0,Formula_Sheet!N30=0), "Fill performance score for Home page first!", "The best recorded performance score was in " & Formula_Sheet!J30 & " devices " & Formula_Sheet!J31 & ", at " & Formula_Sheet!K30 & CHAR(10) & "The worst recorded performance score was in " & Formula_Sheet!M30 & " devices " & Formula_Sheet!M31 & ", at " & Formula_Sheet!N30 & CHAR(10) & "Refer to " & Formula_Sheet!B31 & " tab for the best and worst insight, links for full diagnostic readings and recommendations for improvement." )) -> Kindly add Analysis Timestamp!
B31: 07_Seventh Link | C31: Desktop | D31: 62 | E31: 72
C32: Mobile | D32: 30 | E32: 30
D34: Oct 19, 2025, 11:19:13 AM | E34: Oct 19, 2025, 11:19:13 AM | G34: =IF(OR(ISBLANK(D34),ISBLANK(E34),TEXT(D34,"mmmm d, yyyy, h:mm:ss am/pm")<>D34,TEXT(E34,"mmmm d, yyyy, h:mm:ss am/pm")<>E34), "Kindly add Analysis Timestamp!", IF(OR(Formula_Sheet!K34=0,Formula_Sheet!N34=0), "Fill performance score for Home page first!", "The best recorded performance score was in " & Formula_Sheet!J34 & " devices " & Formula_Sheet!J35 & ", at " & Formula_Sheet!K34 & CHAR(10) & "The worst recorded performance score was in " & Formula_Sheet!M34 & " devices " & Formula_Sheet!M35 & ", at " & Formula_Sheet!N34 & CHAR(10) & "Refer to " & Formula_Sheet!B35 & " tab for the best and worst insight, links for full diagnostic readings and recommendations for improvement." )) -> Kindly add Analysis Timestamp!
B35: 08_Eighth Link | C35: Desktop | D35: 63 | E35: 62
C36: Mobile | D36: 33 | E36: 26
C38: 0 to 49 | D38: Poor | G38: =IF(OR(Formula_Sheet!J39=0,Formula_Sheet!K39=0), "Kindly, fill the Performance Score first!", Formula_Sheet!T61 & Formula_Sheet!T62 & CHAR(10) & Formula_Sheet!T64 & CHAR(10) & CHAR(10) & Formula_Sheet!AF61 & Formula_Sheet!AF62 & CHAR(10) & Formula_Sheet!AF64 ) -> Kindly, fill the Performance Score first!
C39: 50 to 89 | D39: Needs Improvement
C40: 90 to 100 | D40: Good

Sheet 01_First Link
C2: =Summary!D6 -> 0
B3: =Summary!B7 -> 01_First Link | C3: Desktop | D3: With Cache | E3: =HYPERLINK(".\html-10-19-2025-11-08-57-AM\www_w3schools_com-Desktop-Normal.report.html", "https://www.w3schools.com/ — Desktop-Normal")
D4: Without Cache | E4: =HYPERLINK(".\html-10-19-2025-11-08-57-AM\www_w3schools_com-Desktop-Incognito.report.html", "https://www.w3schools.com/ — Desktop-Incognito")
C5: Mobile | D5: With Cache | E5: =HYPERLINK(".\html-10-19-2025-11-08-57-AM\www_w3schools_com-Mobile-Normal.report.html", "https://www.w3schools.com/ — Mobile-Normal")
D6: Without Cache | E6: =HYPERLINK(".\html-10-19-2025-11-08-57-AM\www_w3schools_com-Mobile-Incognito.report.html", "https://www.w3schools.com/ — Mobile-Incognito")
B8: Best Insight
B9: URL: | C9: =E5 -> 0
B10: Diagnostic: | C10: Properly size images
B11: Recommendation: | C11: Learn how to size images
B24: Worst Insight
B25: URL: | C25: =E5 -> 0
B26: Diagnostic: | C26: Reduce JavaScript execution time — 2.2 s
B27: Recommendation: | C27: Learn how to reduce Javascript execution time

Sheet 02_Second Link
C2: =Summary!D10 -> 0
B3: =Summary!B11 -> 02_Second Link | C3: Desktop | D3: With Cache | E3: =HYPERLINK(".\html-10-19-2025-11-08-57-AM\www_w3schools_com_programming_index_php-Desktop-Normal.report.html", "https://www.w3schools.com/programming/index.php — Desktop-Normal")
D4: Without Cache | E4: =HYPERLINK(".\html-10-19-2025-11-08-57-AM\www_w3schools_com_programming_index_php-Desktop-Incognito.report.html", "https://www.w3schools.com/programming/index.php — Desktop-Incognito")
C5: Mobile | D5: With Cache | E5: =HYPERLINK(".\html-10-19-2025-11-08-57-AM\www_w3schools_com_programming_index_php-Mobile-Normal.report.html", "https://www.w3schools.com/programming/index.php — Mobile-Normal")
D6: Without Cache | E6: =HYPERLINK(".\html-10-19-2025-11-08-57-AM\www_w3schools_com_programming_index_php-Mobile-Incognito.report.html", "https://www.w3schools.com/programming/index.php — Mobile-Incognito")
B8: Best Insight
B9: URL: | C9: =E5 -> 0
B10: Diagnostic: | C10: Properly size images
B11: Recommendation: | C11: Learn how to size images
B24: Worst Insight
B25: URL: | C25: =E5 -> 0
B26: Diagnostic: | C26: Reduce JavaScript execution time — 46.6 s
B27: Recommendation: | C27: Learn how to reduce Javascript execution time

Sheet 03_Third Link
C2: =Summary!D14 -> 0
B3: =Summary!B15 -> 03_Third Link | C3: Desktop | D3: With Cache | E3: =HYPERLINK(".\html-10-19-2025-11-08-57-AM\www_w3schools_com_spaces_index_php-Desktop-Normal.report.html", "https://www.w3schools.com/spaces/index.php — Desktop-Normal")
D4: Without Cache | E4: =HYPERLINK(".\html-10-19-2025-11-08-57-AM\www_w3schools_com_spaces_index_php-Desktop-Incognito.report.html", "https://www.w3schools.com/spaces/index.php — Desktop-Incognito")
C5: Mobile | D5: With Cache | E5: =HYPERLINK(".\html-10-19-2025-11-08-57-AM\www_w3schools_com_spaces_index_php-Mobile-Normal.report.html", "https://www.w3schools.com/spaces/index.php — Mobile-Normal")
D6: Without Cache | E6: =HYPERLINK(".\html-10-19-2025-11-08-57-AM\www_w3schools_com_spaces_index_php-Mobile-Incognito.report.html", "https://www.w3schools.com/spaces/index.php — Mobile-Incognito")
B8: Best Insight
B9: URL: | C9: =E5 -> 0
B10: Diagnostic: | C10: Minify CSS
B11: Recommendation: | C11: Learn how to minify CSS
B24: Worst Insight
B25: URL: | C25: =E5 -> 0
B26: Diagnostic: | C26: Minimize main-thread work — 4.2 s
B27: Recommendation: | C27: Learn how to minimize main-thread work

Sheet 04_Fourth Link
A1: \\
C2: =Summary!D18 -> 0
B3: =Summary!B19 -> 04_Fourth Link | C3: Desktop | D3: With Cache | E3: =HYPERLINK(".\html-10-19-2025-11-08-57-AM\www_w3schools_com_codegame_index_html-Desktop-Normal.report.html", "https://www.w3schools.com/codegame/index.html — Desktop-Normal")
D4: Without Cache | E4: =HYPERLINK(".\html-10-19-2025-11-08-57-AM\www_w3schools_com_codegame_index_html-Desktop-Incognito.report.html", "https://www.w3schools.com/codegame/index.html — Desktop-Incognito")
C5: Mobile | D5: With Cache | E5: =HYPERLINK(".\html-10-19-2025-11-08-57-AM\www_w3schools_com_codegame_index_html-Mobile-Normal.report.html", "https://www.w3schools.com/codegame/index.html — Mobile-Normal")
D6: Without Cache | E6: =HYPERLINK(".\html-10-19-2025-11-08-57-AM\www_w3schools_com_codegame_index_html-Mobile-Incognito.report.html", "https://www.w3schools.com/codegame/index.html — Mobile-Incognito")
B8: Best Insight
B9: URL: | C9: =E5 -> 0
B10: Diagnostic: | C10: Properly size images
B11: Recommendation: | C11: Learn how to size images
B24: Worst Insight
B25: URL: | C25: =E5 -> 0
B26: Diagnostic: | C26: Minimize main-thread work — 16.7 s
B27: Recommendation: | C27: Learn how to minimize main-thread work

Sheet 05_Fifth Link
C2: =Summary!D22 -> 0
B3: =Summary!B23 -> 05_Fifth Link | C3: Desktop | D3: With Cache | E3: =HYPERLINK(".\html-10-19-2025-11-08-57-AM\www_w3schools_com_cybersecurity_index_php-Desktop-Normal.report.html", "https://www.w3schools.com/cybersecurity/index.php — Desktop-Normal")
D4: Without Cache | E4: =HYPERLINK(".\html-10-19-2025-11-08-57-AM\www_w3schools_com_cybersecurity_index_php-Desktop-Incognito.report.html", "https://www.w3schools.com/cybersecurity/index.php — Desktop-Incognito")
C5: Mobile | D5: With Cache | E5: =HYPERLINK(".\html-10-19-2025-11-08-57-AM\www_w3schools_com_cybersecurity_index_php-Mobile-Normal.report.html", "https://www.w3schools.com/cybersecurity/index.php — Mobile-Normal")
D6: Without Cache | E6: =HYPERLINK(".\html-10-19-2025-11-08-57-AM\www_w3schools_com_cybersecurity_index_php-Mobile-Incognito.report.html", "https://www.w3schools.com/cybersecurity/index.php — Mobile-Incognito")
B8: Best Insight
B9: URL: | C9: =E5 -> 0
B10: Diagnostic: | C10: Properly size images
B11: Recommendation: | C11: Learn how to size images
B24: Worst Insight
B25: URL: | C25: =E5 -> 0
B26: Diagnostic: | C26: Reduce JavaScript execution time — 57.1 s
B27: Recommendation: | C27: Learn how to reduce Javascript execution time

Sheet 06_Sixth Link
C2: =Summary!D26 -> 0
B3: =Summary!B27 -> 06_Sixth Link | C3: Desktop | D3: With Cache | E3: =HYPERLINK(".\html-10-19-2025-11-08-57-AM\www_w3schools_com_accessibility_index_php-Desktop-Normal.report.html", "https://www.w3schools.com/accessibility/index.php — Desktop-Normal")
D4: Without Cache | E4: =HYPERLINK(".\html-10-19-2025-11-08-57-AM\www_w3schools_com_accessibility_index_php-Desktop-Incognito.report.html", "https://www.w3schools.com/accessibility/index.php — Desktop-Incognito")
C5: Mobile | D5: With Cache | E5: =HYPERLINK(".\html-10-19-2025-11-08-57-AM\www_w3schools_com_accessibility_index_php-Mobile-Normal.report.html", "https://www.w3schools.com/accessibility/index.php — Mobile-Normal")
D6: Without Cache | E6: =HYPERLINK(".\html-10-19-2025-11-08-57-AM\www_w3schools_com_accessibility_index_php-Mobile-Incognito.report.html", "https://www.w3schools.com/accessibility/index.php — Mobile-Incognito")
B8: Best Insight
B9: URL: | C9: =E5 -> 0
B10: Diagnostic: | C10: Properly size images
B11: Recommendation: | C11: Learn how to size images
B24: Worst Insight
B25: URL: | C25: =E5 -> 0
B26: Diagnostic: | C26: Minimize main-thread work — 64.5 s
B27: Recommendation: | C27: Learn how to minimize main-thread work

Sheet 07_Seventh Link
C2: =Summary!D30 -> 0
B3: =Summary!B31 -> 07_Seventh Link | C3: Desktop | D3: With Cache | E3: =HYPERLINK(".\html-10-19-2025-11-08-57-AM\www_w3schools_com_academy_index_php-Desktop-Normal.report.html", "https://www.w3schools.com/academy/index.php — Desktop-Normal")
D4: Without Cache | E4: =HYPERLINK(".\html-10-19-2025-11-08-57-AM\www_w3schools_com_academy_index_php-Desktop-Incognito.report.html", "https://www.w3schools.com/academy/index.php — Desktop-Incognito")
C5: Mobile | D5: With Cache | E5: =HYPERLINK(".\html-10-19-2025-11-08-57-AM\www_w3schools_com_academy_index_php-Mobile-Normal.report.html", "https://www.w3schools.com/academy/index.php — Mobile-Normal")
D6: Without Cache | E6: =HYPERLINK(".\html-10-19-2025-11-08-57-AM\www_w3schools_com_academy_index_php-Mobile-Incognito.report.html", "https://www.w3schools.com/academy/index.php — Mobile-Incognito")
B8: Best Insight
B9: URL: | C9: =E5 -> 0
B10: Diagnostic: | C10: Minify CSS
B11: Recommendation: | C11: Learn how to minify CSS
B24: Worst Insight
B25: URL: | C25: =E5 -> 0
B26: Diagnostic: | C26: Minimize main-thread work — 9.0 s
B27: Recommendation: | C27: Learn how to minimize main-thread work

Sheet 08_Eighth Link
C2: =Summary!D34 -> 0
B3: =Summary!B35 -> 08_Eighth Link | C3: Desktop | D3: With Cache | E3: =HYPERLINK(".\html-10-19-2025-11-08-57-AM\campus_w3schools_com_pages_newsletter-Desktop-Normal.report.html", "https://campus.w3schools.com/pages/newsletter — Desktop-Normal")
D4: Without Cache | E4: =HYPERLINK(".\html-10-19-2025-11-08-57-AM\campus_w3schools_com_pages_newsletter-Desktop-Incognito.report.html", "https://campus.w3schools.com/pages/newsletter — Desktop-Incognito")
C5: Mobile | D5: With Cache | E5: =HYPERLINK(".\html-10-19-2025-11-08-57-AM\campus_w3schools_com_pages_newsletter-Mobile-Normal.report.html", "https://campus.w3schools.com/pages/newsletter — Mobile-Normal")
D6: Without Cache | E6: =HYPERLINK(".\html-10-19-2025-11-08-57-AM\campus_w3schools_com_pages_newsletter-Mobile-Incognito.report.html", "https://campus.w3schools.com/pages/newsletter — Mobile-Incognito")
B8: Best Insight
B9: URL: | C9: =E5 -> 0
B10: Diagnostic: | C10: Eliminate render-blocking resources
B11: Recommendation: | C11: Learn how to eliminate render-blocking resources
B24: Worst Insight
B25: URL: | C25: =E5 -> 0
B26: Diagnostic: | C26: Minimize main-thread work — 17.1 s
B27: Recommendation: | C27: Learn how to minimize main-thread work

Sheet Formula_Sheet
T4: TIE HIGHEST PERFORMANCE SCORE FORMULA | AF4: TIE LOWEST PERFORMANCE SCORE FORMULA
I5: =Summary!B7 -> 01_First Link | J5: Best | K5: Performance Value | L5: Device Selector | M5: Worst | N5: Performance Value | O5: Device Selector | P5: Cell with Highest | Q5: Cell with Lowest | T5: Highest PS/Device | U5: isEqual? | V5: notEqual? Just get max number | W5: Loc | X5: w & w/ cache? | Y5: What device | Z5: HIGHEST SCORE | AA5: same device are false? | AB5: OVERALL HIGHEST PS | AF5: Lowest PS/Device | AG5: isEqual? | AH5: notEqual? Just get lowest number | AI5: Loc | AJ5: w & w/ cache? | AK5: What device | AL5: LOWEST SCORE | AM5: same device are false? | AN5: OVERALL LOWEST PS
I6: Device: | J6: {=IF(L6="Desktop", "Desktop", IF(L6="Mobile", "Mobile", INDIRECT(L6)))} -> Desktop | K6: =IF(AND(U6=TRUE, AB6=TRUE), AB6, MAX(Summary!D7:'Summary'!E8)) -> 0 | L6: =IF(NOT(AA6=FALSE), AA6, IF(LEFT(MID(P6,FIND("!",P6)+1,LEN(P6)),1)="D", LEFT(P6,FIND("!",P6)) & CHAR(CODE(LEFT(MID(P6,FIND("!",P6)+1,LEN(P6)),1))-1) & MID(P6,FIND("!",P6)+2,LEN(P6)), LEFT(P6,FIND("!",P6)) & CHAR(CODE(LEFT(MID(P6,FIND("!",P6)+1,LEN(P6)),1))-2) & MID(P6,FIND("!",P6)+2,LEN(P6)))) -> Desktop | M6: {=IF(O6="Desktop", "Desktop", IF(O6="Mobile", "Mobile", INDIRECT(O6)))} -> Desktop | N6: =IF(AND(AG6=TRUE, AN6=TRUE), AN6, MIN(Summary!D7:'Summary'!E8)) -> 0 | O6: =IF(NOT(AM6=FALSE), AM6, IF(LEFT(MID(Q6,FIND("!",Q6)+1,LEN(Q6)),1)="D", LEFT(Q6,FIND("!",Q6)) & CHAR(CODE(LEFT(MID(Q6,FIND("!",Q6)+1,LEN(Q6)),1))-1) & MID(Q6,FIND("!",Q6)+2,LEN(Q6)), LEFT(Q6,FIND("!",Q6)) & CHAR(CODE(LEFT(MID(Q6,FIND("!",Q6)+1,LEN(Q6)),1))-2) & MID(Q6,FIND("!",Q6)+2,LEN(Q6)))) -> Desktop | P6: {="Summary!" & ADDRESS(MIN(IF(Summary!D7:E8=K6,ROW(Summary!D7:E8))), MIN(IF(Summary!D7:E8=K6,COLUMN(Summary!D7:E8))), 4)} -> Summary!D7 | Q6: {="Summary!" & ADDRESS(MIN(IF(Summary!D7:E8=N6,ROW(Summary!D7:E8))), MIN(IF(Summary!D7:E8=N6,COLUMN(Summary!D7:E8))), 4)} -> Summary!D7 | T6: =MAX(Summary!D7:E7) -> 0 | U6: =IF(T6=T7, TRUE, FALSE) -> TRUE | V6: =IF(U6=TRUE, FALSE, MAX(Summary!D7:E8)) -> FALSE | W6: {=IF(V6=FALSE, FALSE, ADDRESS(MAX(IF(Summary!D7:E8=V6,ROW(Summary!D7:E8))), MAX(IF(Summary!D7:E8=V6,COLUMN(Summary!D7:E8))), 4))} -> FALSE | X6: =IF(U6=TRUE, IF(Summary!E7=Summary!D7, TRUE, FALSE),FALSE) -> TRUE | Y6: =IF(X6=TRUE, "Desktop") -> Desktop | Z6: =IF(AND(Y6="Desktop", U6=TRUE), T6, FALSE) -> 0 | AA6: =IF(NOT(Z6=FALSE), Y6, IF(NOT(Z7=FALSE),Y7, FALSE)) -> Desktop | AB6: =IF(NOT(Z6=FALSE), Z6, IF(NOT(Z7=FALSE), Z7, V6)) -> 0 | AF6: =MIN(Summary!D7:E7) -> 0 | AG6: =IF(AF6=AF7, TRUE, FALSE) -> TRUE | AH6: =IF(AG6=TRUE, FALSE, MIN(Summary!D7:E8)) -> FALSE | AI6: {=IF(AH6=FALSE, FALSE, ADDRESS(MIN(IF(Summary!D7:E8=AH6,ROW(Summary!D7:E8))), MIN(IF(Summary!D7:E8=AH6,COLUMN(Summary!D7:E8))), 4))} -> FALSE | AJ6: =IF(AG6=TRUE, IF(Summary!D7=Summary!E7, TRUE, FALSE),FALSE) -> TRUE | AK6: =IF(AJ6=TRUE, "Desktop") -> Desktop | AL6: =IF(AND(AK6="Desktop", AG6=TRUE), AF6, FALSE) -> 0 | AM6: =IF(NOT(AL6=FALSE), AK6, IF(NOT(AL7=FALSE),AK7, FALSE)) -> Desktop | AN6: =IF(NOT(AL6=FALSE), AL6, IF(NOT(AL7=FALSE), AL7, AH6)) -> 0
I7: Cache: | J7: =IF(J6="Desktop",IF(Summary!D7=Summary!E7,"with and without cache",(IF(Summary!D7>Summary!E7,"with cache","without cache"))),IF(Summary!D8=Summary!E8,"with and without cache",(IF(Summary!D8>Summary!E8,"with cache","without cache")))) -> with and without cache | M7: =IF(M6="Desktop",IF(Summary!D7=Summary!E7,"with and without cache",IF(Summary!D7<Summary!E7,"with cache","without cache")),IF(Summary!D8=Summary!E8,"with and without cache",IF(Summary!D8<Summary!E8,"with cache","without cache"))) -> with and without cache | T7: =MAX(Summary!D8:E8) -> 0 | U7: =IF(T6=T7, TRUE, FALSE) -> TRUE | V7: =IF(U7=TRUE, FALSE, MAX(Summary!D8:E9)) -> FALSE | W7: {=IF(V7=FALSE, FALSE, ADDRESS(MAX(IF(Summary!D8:E9=V7,ROW(Summary!D8:E9))), MAX(IF(Summary!D8:E9=V7,COLUMN(Summary!D8:E9))), 4))} -> FALSE | X7: =IF(U7=TRUE, IF(Summary!E8=Summary!D8, TRUE, FALSE),FALSE) -> TRUE | Y7: =IF(X7=TRUE, "Mobile") -> Mobile | Z7: =IF(AND(Y7="Mobile", U7=TRUE), T7, FALSE) -> 0 | AF7: =MIN(Summary!D8:E8) -> 0 | AG7: =IF(AF6=AF7, TRUE, FALSE) -> TRUE | AH7: =IF(AG7=TRUE, FALSE, MIN(Summary!D8:E9)) -> FALSE | AI7: {=IF(AH7=FALSE, FALSE, ADDRESS(MIN(IF(Summary!D7:E8=AH7,ROW(Summary!D7:E8))), MIN(IF(Summary!D7:E8=AH7,COLUMN(Summary!D7:E8))), 4))} -> FALSE | AJ7: =IF(AG7=TRUE, IF(Summary!D8=Summary!E8, TRUE, FALSE),FALSE) -> TRUE | AK7: =IF(AJ7=TRUE, "Mobile") -> Mobile | AL7: =IF(AND(AK7="Mobile", AG7=TRUE), AF7, FALSE) -> 0
I9: =Summary!B11 -> 02_Second Link | J9: Best | K9: Performance Value | L9: Device Selector | M9: Worst | N9: Performance Value | O9: Device Selector | P9: Cell with Highest | Q9: Cell with Lowest | T9: Highest PS/Device | U9: isEqual? | V9: notEqual? Just get max number | W9: Loc | X9: w & w/ cache? | Y9: What device | Z9: HIGHEST SCORE | AA9: same device are false? | AB9: OVERALL HIGHEST PS | AF9: Lowest PS/Device | AG9: isEqual? | AH9: notEqual? Just get lowest number | AI9: Loc | AJ9: w & w/ cache? | AK9: What device | AL9: LOWEST SCORE | AM9: same device are false? | AN9: OVERALL LOWEST PS
I10: Device: | J10: {=IF(L10="Desktop", "Desktop", IF(L10="Mobile", "Mobile", INDIRECT(L10)))} -> Desktop | K10: =IF(AND(U10=TRUE, AB10=TRUE), AB10, MAX(Summary!D11:'Summary'!E12)) -> 0 | L10: =IF(NOT(AA10=FALSE), AA10, IF(LEFT(MID(P10,FIND("!",P10)+1,LEN(P10)),1)="D", LEFT(P10,FIND("!",P10)) & CHAR(CODE(LEFT(MID(P10,FIND("!",P10)+1,LEN(P10)),1))-1) & MID(P10,FIND("!",P10)+2,LEN(P10)), LEFT(P10,FIND("!",P10)) & CHAR(CODE(LEFT(MID(P10,FIND("!",P10)+1,LEN(P10)),1))-2) & MID(P10,FIND("!",P10)+2,LEN(P10)))) -> Desktop | M10: {=IF(O10="Desktop", "Desktop", IF(O10="Mobile", "Mobile", INDIRECT(O10)))} -> Desktop | N10: =IF(AND(AG10=TRUE, AN10=TRUE), AN10, MIN(Summary!D11:'Summary'!E12)) -> 0 | O10: =IF(NOT(AM10=FALSE), AM10, IF(LEFT(MID(Q10,FIND("!",Q10)+1,LEN(Q10)),1)="D", LEFT(Q10,FIND("!",Q10)) & CHAR(CODE(LEFT(MID(Q10,FIND("!",Q10)+1,LEN(Q10)),1))-1) & MID(Q10,FIND("!",Q10)+2,LEN(Q10)), LEFT(Q10,FIND("!",Q10)) & CHAR(CODE(LEFT(MID(Q10,FIND("!",Q10)+1,LEN(Q10)),1))-2) & MID(Q10,FIND("!",Q10)+2,LEN(Q10)))) -> Desktop | P10: {="Summary!" & ADDRESS(MIN(IF(Summary!D11:E12=K10,ROW(Summary!D11:E12))), MIN(IF(Summary!D11:E12=K10,COLUMN(Summary!D11:E12))), 4)} -> Summary!D11 | Q10: {="Summary!" & ADDRESS(MIN(IF(Summary!D11:E12=N10,ROW(Summary!D11:E12))), MIN(IF(Summary!D11:E12=N10,COLUMN(Summary!D11:E12))), 4)} -> Summary!D11 | T10: =MAX(Summary!D11:E11) -> 0 | U10: =IF(T10=T11, TRUE, FALSE) -> TRUE | V10: =IF(U10=TRUE, FALSE, MAX(Summary!D11:E12)) -> FALSE | W10: {=IF(V10=FALSE, FALSE, ADDRESS(MAX(IF(Summary!D11:E12=V10,ROW(Summary!D11:E12))), MAX(IF(Summary!D11:E12=V10,COLUMN(Summary!D11:E12))), 4))} -> FALSE | X10: =IF(U10=TRUE, IF(Summary!E11=Summary!D11, TRUE, FALSE),FALSE) -> TRUE | Y10: =IF(X10=TRUE, "Desktop") -> Desktop | Z10: =IF(AND(Y10="Desktop", U10=TRUE), T10, FALSE) -> 0 | AA10: =IF(NOT(Z10=FALSE), Y10, IF(NOT(Z11=FALSE),Y11, FALSE)) -> Desktop | AB10: =IF(NOT(Z10=FALSE), Z10, IF(NOT(Z11=FALSE), Z11, V10)) -> 0 | AF10: =MIN(Summary!D11:E11) -> 0 | AG10: =IF(AF10=AF11, TRUE, FALSE) -> TRUE | AH10: =IF(AG10=TRUE, FALSE, MIN(Summary!D11:E12)) -> FALSE | AI10: {=IF(AH10=FALSE, FALSE, ADDRESS(MIN(IF(Summary!D11:E12=AH10,ROW(Summary!D11:E12))), MIN(IF(Summary!D11:E12=AH10,COLUMN(Summary!D11:E12))), 4))} -> FALSE | AJ10: =IF(AG10=TRUE, IF(Summary!D11=Summary!E11, TRUE, FALSE),FALSE) -> TRUE | AK10: =IF(AJ10=TRUE, "Desktop") -> Desktop | AL10: =IF(AND(AK10="Desktop", AG10=TRUE), AF10, FALSE) -> 0 | AM10: =IF(NOT(AL10=FALSE), AK10, IF(NOT(AL11=FALSE),AK11, FALSE)) -> Desktop | AN10: =IF(NOT(AL10=FALSE), AL10, IF(NOT(AL11=FALSE), AL11, AH10)) -> 0
I11: Cache: | J11: =IF(J10="Desktop",IF(Summary!D11=Summary!E11,"with and without cache",(IF(Summary!D11>Summary!E11,"with cache","without cache"))),IF(Summary!D12=Summary!E12,"with and without cache",(IF(Summary!D12>Summary!E12,"with cache","without cache")))) -> with and without cache | M11: =IF(M10="Desktop",IF(Summary!D11=Summary!E11,"with and without cache",IF(Summary!D11<Summary!E11,"with cache","without cache")),IF(Summary!D12=Summary!E12,"with and without cache",IF(Summary!D12<Summary!E12,"with cache","without cache"))) -> with and without cache | T11: =MAX(Summary!D12:E12) -> 0 | U11: =IF(T10=T11, TRUE, FALSE) -> TRUE | V11: =IF(U11=TRUE, FALSE, MAX(Summary!D12:E13)) -> FALSE | W11: {=IF(V11=FALSE, FALSE, ADDRESS(MAX(IF(Summary!D12:E13=V11,ROW(Summary!D12:E13))), MAX(IF(Summary!D12:E13=V11,COLUMN(Summary!D12:E13))), 4))} -> FALSE | X11: =IF(U11=TRUE, IF(Summary!E12=Summary!D12, TRUE, FALSE),FALSE) -> TRUE | Y11: =IF(X11=TRUE, "Mobile") -> Mobile | Z11: =IF(AND(Y11="Mobile", U11=TRUE), T11, FALSE) -> 0 | AF11: =MIN(Summary!D12:E12) -> 0 | AG11: =IF(AF10=AF11, TRUE, FALSE) -> TRUE | AH11: =IF(AG11=TRUE, FALSE, MIN(Summary!D12:E13)) -> FALSE | AI11: {=IF(AH11=FALSE, FALSE, ADDRESS(MIN(IF(Summary!D11:E12=AH11,ROW(Summary!D11:E12))), MIN(IF(Summary!D11:E12=AH11,COLUMN(Summary!D11:E12))), 4))} -> FALSE | AJ11: =IF(AG11=TRUE, IF(Summary!D12=Summary!E12, TRUE, FALSE),FALSE) -> TRUE | AK11: =IF(AJ11=TRUE, "Mobile") -> Mobile | AL11: =IF(AND(AK11="Mobile", AG11=TRUE), AF11, FALSE) -> 0
I13: =Summary!B15 -> 03_Third Link | J13: Best | K13: Performance Value | L13: Device Selector | M13: Worst | N13: Performance Value | O13: Device Selector | P13: Cell with Highest | Q13: Cell with Lowest | T13: Highest PS/Device | U13: isEqual? | V13: notEqual? Just get max number | W13: Loc | X13: w & w/ cache? | Y13: What device | Z13: HIGHEST SCORE | AA13: same device are false? | AB13: OVERALL HIGHEST PS | AF13: Lowest PS/Device | AG13: isEqual? | AH13: notEqual? Just get lowest number | AI13: Loc | AJ13: w & w/ cache? | AK13: What device | AL13: LOWEST SCORE | AM13: same device are false? | AN13: OVERALL LOWEST PS
I14: Device: | J14: {=IF(L14="Desktop", "Desktop", IF(L14="Mobile", "Mobile", INDIRECT(L14)))} -> Desktop | K14: =IF(AND(U14=TRUE, AB14=TRUE), AB14, MAX(Summary!D15:'Summary'!E16)) -> 0 | L14: =IF(NOT(AA14=FALSE), AA14, IF(LEFT(MID(P14,FIND("!",P14)+1,LEN(P14)),1)="D", LEFT(P14,FIND("!",P14)) & CHAR(CODE(LEFT(MID(P14,FIND("!",P14)+1,LEN(P14)),1))-1) & MID(P14,FIND("!",P14)+2,LEN(P14)), LEFT(P14,FIND("!",P14)) & CHAR(CODE(LEFT(MID(P14,FIND("!",P14)+1,LEN(P14)),1))-2) & MID(P14,FIND("!",P14)+2,LEN(P14)))) -> Desktop | M14: {=IF(O14="Desktop", "Desktop", IF(O14="Mobile", "Mobile", INDIRECT(O14)))} -> Desktop | N14: =IF(AND(AG14=TRUE, AN14=TRUE), AN14, MIN(Summary!D15:'Summary'!E16)) -> 0 | O14: =IF(NOT(AM14=FALSE), AM14, IF(LEFT(MID(Q14,FIND("!",Q14)+1,LEN(Q14)),1)="D", LEFT(Q14,FIND("!",Q14)) & CHAR(CODE(LEFT(MID(Q14,FIND("!",Q14)+1,LEN(Q14)),1))-1) & MID(Q14,FIND("!",Q14)+2,LEN(Q14)), LEFT(Q14,FIND("!",Q14)) & CHAR(CODE(LEFT(MID(Q14,FIND("!",Q14)+1,LEN(Q14)),1))-2) & MID(Q14,FIND("!",Q14)+2,LEN(Q14)))) -> Desktop | P14: {="Summary!" & ADDRESS(MIN(IF(Summary!D15:E16=K14,ROW(Summary!D15:E16))), MIN(IF(Summary!D15:E16=K14,COLUMN(Summary!D15:E16))), 4)} -> Summary!D15 | Q14: {="Summary!" & ADDRESS(MIN(IF(Summary!D15:E16=N14,ROW(Summary!D15:E16))), MIN(IF(Summary!D15:E16=N14,COLUMN(Summary!D15:E16))), 4)} -> Summary!D15 | T14: =MAX(Summary!D15:E15) -> 0 | U14: =IF(T14=T15, TRUE, FALSE) -> TRUE | V14: =IF(U14=TRUE, FALSE, MAX(Summary!D15:E16)) -> FALSE | W14: {=IF(V14=FALSE, FALSE, ADDRESS(MAX(IF(Summary!D15:E16=V14,ROW(Summary!D15:E16))), MAX(IF(Summary!D15:E16=V14,COLUMN(Summary!D15:E16))), 4))} -> FALSE | X14: =IF(U14=TRUE, IF(Summary!E15=Summary!D15, TRUE, FALSE),FALSE) -> TRUE | Y14: =IF(X14=TRUE, "Desktop") -> Desktop | Z14: =IF(AND(Y14="Desktop", U14=TRUE), T14, FALSE) -> 0 | AA14: =IF(NOT(Z14=FALSE), Y14, IF(NOT(Z15=FALSE),Y15, FALSE)) -> Desktop | AB14: =IF(NOT(Z14=FALSE), Z14, IF(NOT(Z15=FALSE), Z15, V14)) -> 0 | AF14: =MIN(Summary!D15:E15) -> 0 | AG14: =IF(AF14=AF15, TRUE, FALSE) -> TRUE | AH14: =IF(AG14=TRUE, FALSE, MIN(Summary!D15:E16)) -> FALSE | AI14: {=IF(AH14=FALSE, FALSE, ADDRESS(MIN(IF(Summary!D15:E16=AH14,ROW(Summary!D15:E16))), MIN(IF(Summary!D15:E16=AH14,COLUMN(Summary!D15:E16))), 4))} -> FALSE | AJ14: =IF(AG14=TRUE, IF(Summary!D15=Summary!E15, TRUE, FALSE),FALSE) -> TRUE | AK14: =IF(AJ14=TRUE, "Desktop") -> Desktop | AL14: =IF(AND(AK14="Desktop", AG14=TRUE), AF14, FALSE) -> 0 | AM14: =IF(NOT(AL14=FALSE), AK14, IF(NOT(AL15=FALSE),AK15, FALSE)) -> Desktop | AN14: =IF(NOT(AL14=FALSE), AL14, IF(NOT(AL15=FALSE), AL15, AH14)) -> 0
I15: Cache: | J15: =IF(J14="Desktop",IF(Summary!D15=Summary!E15,"with and without cache",(IF(Summary!D15>Summary!E15,"with cache","without cache"))),IF(Summary!D16=Summary!E16,"with and without cache",(IF(Summary!D16>Summary!E16,"with cache","without cache")))) -> with and without cache | M15: =IF(M14="Desktop",IF(Summary!D15=Summary!E15,"with and without cache",IF(Summary!D15<Summary!E15,"with cache","without cache")),IF(Summary!D16=Summary!E16,"with and without cache",IF(Summary!D16<Summary!E16,"with cache","without cache"))) -> with and without cache | T15: =MAX(Summary!D16:E16) -> 0 | U15: =IF(T14=T15, TRUE, FALSE) -> TRUE | V15: =IF(U15=TRUE, FALSE, MAX(Summary!D16:E17)) -> FALSE | W15: {=IF(V15=FALSE, FALSE, ADDRESS(MAX(IF(Summary!D16:E17=V15,ROW(Summary!D16:E17))), MAX(IF(Summary!D16:E17=V15,COLUMN(Summary!D16:E17))), 4))} -> FALSE | X15: =IF(U15=TRUE, IF(Summary!E16=Summary!D16, TRUE, FALSE),FALSE) -> TRUE | Y15: =IF(X15=TRUE, "Mobile") -> Mobile | Z15: =IF(AND(Y15="Mobile", U15=TRUE), T15, FALSE) -> 0 | AF15: =MIN(Summary!D16:E16) -> 0 | AG15: =IF(AF14=AF15, TRUE, FALSE) -> TRUE | AH15: =IF(AG15=TRUE, FALSE, MIN(Summary!D16:E17)) -> FALSE | AI15: {=IF(AH15=FALSE, FALSE, ADDRESS(MIN(IF(Summary!D15:E16=AH15,ROW(Summary!D15:E16))), MIN(IF(Summary!D15:E16=AH15,COLUMN(Summary!D15:E16))), 4))} -> FALSE | AJ15: =IF(AG15=TRUE, IF(Summary!D16=Summary!E16, TRUE, FALSE),FALSE) -> TRUE | AK15: =IF(AJ15=TRUE, "Mobile") -> Mobile | AL15: =IF(AND(AK15="Mobile", AG15=TRUE), AF15, FALSE) -> 0
I17: =Summary!B19 -> 04_Fourth Link | J17: Best | K17: Performance Value | L17: Device Selector | M17: Worst | N17: Performance Value | O17: Device Selector | P17: Cell with Highest | Q17: Cell with Lowest | T17: Highest PS/Device | U17: isEqual? | V17: notEqual? Just get max number | W17: Loc | X17: w & w/ cache? | Y17: What device | Z17: HIGHEST SCORE | AA17: same device are false? | AB17: OVERALL HIGHEST PS | AF17: Lowest PS/Device | AG17: isEqual? | AH17: notEqual? Just get lowest number | AI17: Loc | AJ17: w & w/ cache? | AK17: What device | AL17: LOWEST SCORE | AM17: same device are false? | AN17: OVERALL LOWEST PS
I18: Device: | J18: {=IF(L18="Desktop", "Desktop", IF(L18="Mobile", "Mobile", INDIRECT(L18)))} -> Desktop | K18: =IF(AND(U18=TRUE, AB18=TRUE), AB18, MAX(Summary!D19:'Summary'!E20)) -> 0 | L18: =IF(NOT(AA18=FALSE), AA18, IF(LEFT(MID(P18,FIND("!",P18)+1,LEN(P18)),1)="D", LEFT(P18,FIND("!",P18)) & CHAR(CODE(LEFT(MID(P18,FIND("!",P18)+1,LEN(P18)),1))-1) & MID(P18,FIND("!",P18)+2,LEN(P18)), LEFT(P18,FIND("!",P18)) & CHAR(CODE(LEFT(MID(P18,FIND("!",P18)+1,LEN(P18)),1))-2) & MID(P18,FIND("!",P18)+2,LEN(P18)))) -> Desktop | M18: {=IF(O18="Desktop", "Desktop", IF(O18="Mobile", "Mobile", INDIRECT(O18)))} -> Desktop | N18: =IF(AND(AG18=TRUE, AN18=TRUE), AN18, MIN(Summary!D19:'Summary'!E20)) -> 0 | O18: =IF(NOT(AM18=FALSE), AM18, IF(LEFT(MID(Q18,FIND("!",Q18)+1,LEN(Q18)),1)="D", LEFT(Q18,FIND("!",Q18)) & CHAR(CODE(LEFT(MID(Q18,FIND("!",Q18)+1,LEN(Q18)),1))-1) & MID(Q18,FIND("!",Q18)+2,LEN(Q18)), LEFT(Q18,FIND("!",Q18)) & CHAR(CODE(LEFT(MID(Q18,FIND("!",Q18)+1,LEN(Q18)),1))-2) & MID(Q18,FIND("!",Q18)+2,LEN(Q18)))) -> Desktop | P18: {="Summary!" & ADDRESS(MIN(IF(Summary!D19:E20=K18,ROW(Summary!D19:E20))), MIN(IF(Summary!D19:E20=K18,COLUMN(Summary!D19:E20))), 4)} -> Summary!D19 | Q18: {="Summary!" & ADDRESS(MIN(IF(Summary!D19:E20=N18,ROW(Summary!D19:E20))), MIN(IF(Summary!D19:E20=N18,COLUMN(Summary!D19:E20))), 4)} -> Summary!D19 | T18: =MAX(Summary!D19:E19) -> 0 | U18: =IF(T18=T19, TRUE, FALSE) -> TRUE | V18: =IF(U18=TRUE, FALSE, MAX(Summary!D19:E20)) -> FALSE | W18: {=IF(V18=FALSE, FALSE, ADDRESS(MAX(IF(Summary!D19:E20=V18,ROW(Summary!D19:E20))), MAX(IF(Summary!D19:E20=V18,COLUMN(Summary!D19:E20))), 4))} -> FALSE | X18: =IF(U18=TRUE, IF(Summary!E19=Summary!D19, TRUE, FALSE),FALSE) -> TRUE | Y18: =IF(X18=TRUE, "Desktop") -> Desktop | Z18: =IF(AND(Y18="Desktop", U18=TRUE), T18, FALSE) -> 0 | AA18: =IF(NOT(Z18=FALSE), Y18, IF(NOT(Z19=FALSE),Y19, FALSE)) -> Desktop | AB18: =IF(NOT(Z18=FALSE), Z18, IF(NOT(Z19=FALSE), Z19, V18)) -> 0 | AF18: =MIN(Summary!D19:E19) -> 0 | AG18: =IF(AF18=AF19, TRUE, FALSE) -> TRUE | AH18: =IF(AG18=TRUE, FALSE, MIN(Summary!D19:E20)) -> FALSE | AI18: {=IF(AH18=FALSE, FALSE, ADDRESS(MIN(IF(Summary!D19:E20=AH18,ROW(Summary!D19:E20))), MIN(IF(Summary!D19:E20=AH18,COLUMN(Summary!D19:E20))), 4))} -> FALSE | AJ18: =IF(AG18=TRUE, IF(Summary!D19=Summary!E19, TRUE, FALSE),FALSE) -> TRUE | AK18: =IF(AJ18=TRUE, "Desktop") -> Desktop | AL18: =IF(AND(AK18="Desktop", AG18=TRUE), AF18, FALSE) -> 0 | AM18: =IF(NOT(AL18=FALSE), AK18, IF(NOT(AL19=FALSE),AK19, FALSE)) -> Desktop | AN18: =IF(NOT(AL18=FALSE), AL18, IF(NOT(AL19=FALSE), AL19, AH18)) -> 0
I19: Cache: | J19: =IF(J18="Desktop",IF(Summary!D19=Summary!E19,"with and without cache",(IF(Summary!D19>Summary!E19,"with cache","without cache"))),IF(Summary!D20=Summary!E20,"with and without cache",(IF(Summary!D20>Summary!E20,"with cache","without cache")))) -> with and without cache | M19: =IF(M18="Desktop",IF(Summary!D19=Summary!E19,"with and without cache",IF(Summary!D19<Summary!E19,"with cache","without cache")),IF(Summary!D20=Summary!E20,"with and without cache",IF(Summary!D20<Summary!E20,"with cache","without cache"))) -> with and without cache | T19: =MAX(Summary!D20:E20) -> 0 | U19: =IF(T18=T19, TRUE, FALSE) -> TRUE | V19: =IF(U19=TRUE, FALSE, MAX(Summary!D20:E21)) -> FALSE | W19: {=IF(V19=FALSE, FALSE, ADDRESS(MAX(IF(Summary!D20:E21=V19,ROW(Summary!D20:E21))), MAX(IF(Summary!D20:E21=V19,COLUMN(Summary!D20:E21))), 4))} -> FALSE | X19: =IF(U19=TRUE, IF(Summary!E20=Summary!D20, TRUE, FALSE),FALSE) -> TRUE | Y19: =IF(X19=TRUE, "Mobile") -> Mobile | Z19: =IF(AND(Y19="Mobile", U19=TRUE), T19, FALSE) -> 0 | AF19: =MIN(Summary!D20:E20) -> 0 | AG19: =IF(AF18=AF19, TRUE, FALSE) -> TRUE | AH19: =IF(AG19=TRUE, FALSE, MIN(Summary!D20:E21)) -> FALSE | AI19: {=IF(AH19=FALSE, FALSE, ADDRESS(MIN(IF(Summary!D19:E20=AH19,ROW(Summary!D19:E20))), MIN(IF(Summary!D19:E20=AH19,COLUMN(Summary!D19:E20))), 4))} -> FALSE | AJ19: =IF(AG19=TRUE, IF(Summary!D20=Summary!E20, TRUE, FALSE),FALSE) -> TRUE | AK19: =IF(AJ19=TRUE, "Mobile") -> Mobile | AL19: =IF(AND(AK19="Mobile", AG19=TRUE), AF19, FALSE) -> 0
I21: =Summary!B23 -> 05_Fifth Link | J21: Best | K21: Performance Value | L21: Device Selector | M21: Worst | N21: Performance Value | O21: Device Selector | P21: Cell with Highest | Q21: Cell with Lowest | T21: Highest PS/Device | U21: isEqual? | V21: notEqual? Just get max number | W21: Loc | X21: w & w/ cache? | Y21: What device | Z21: HIGHEST SCORE | AA21: same device are false? | AB21: OVERALL HIGHEST PS | AF21: Lowest PS/Device | AG21: isEqual? | AH21: notEqual? Just get lowest number | AI21: Loc | AJ21: w & w/ cache? | AK21: What device | AL21: LOWEST SCORE | AM21: same device are false? | AN21: OVERALL LOWEST PS
I22: Device: | J22: {=IF(L22="Desktop", "Desktop", IF(L22="Mobile", "Mobile", INDIRECT(L22)))} -> Desktop | K22: =IF(AND(U22=TRUE, AB22=TRUE), AB22, MAX(Summary!D23:'Summary'!E24)) -> 0 | L22: =IF(NOT(AA22=FALSE), AA22, IF(LEFT(MID(P22,FIND("!",P22)+1,LEN(P22)),1)="D", LEFT(P22,FIND("!",P22)) & CHAR(CODE(LEFT(MID(P22,FIND("!",P22)+1,LEN(P22)),1))-1) & MID(P22,FIND("!",P22)+2,LEN(P22)), LEFT(P22,FIND("!",P22)) & CHAR(CODE(LEFT(MID(P22,FIND("!",P22)+1,LEN(P22)),1))-2) & MID(P22,FIND("!",P22)+2,LEN(P22)))) -> Desktop | M22: {=IF(O22="Desktop", "Desktop", IF(O22="Mobile", "Mobile", INDIRECT(O22)))} -> Desktop | N22: =IF(AND(AG22=TRUE, AN22=TRUE), AN22, MIN(Summary!D23:'Summary'!E24)) -> 0 | O22: =IF(NOT(AM22=FALSE), AM22, IF(LEFT(MID(Q22,FIND("!",Q22)+1,LEN(Q22)),1)="D", LEFT(Q22,FIND("!",Q22)) & CHAR(CODE(LEFT(MID(Q22,FIND("!",Q22)+1,LEN(Q22)),1))-1) & MID(Q22,FIND("!",Q22)+2,LEN(Q22)), LEFT(Q22,FIND("!",Q22)) & CHAR(CODE(LEFT(MID(Q22,FIND("!",Q22)+1,LEN(Q22)),1))-2) & MID(Q22,FIND("!",Q22)+2,LEN(Q22)))) -> Desktop | P22: {="Summary!" & ADDRESS(MIN(IF(Summary!D23:E24=K22,ROW(Summary!D23:E24))), MIN(IF(Summary!D23:E24=K22,COLUMN(Summary!D23:E24))), 4)} -> Summary!D23 | Q22: {="Summary!" & ADDRESS(MIN(IF(Summary!D23:E24=N22,ROW(Summary!D23:E24))), MIN(IF(Summary!D23:E24=N22,COLUMN(Summary!D23:E24))), 4)} -> Summary!D23 | T22: =MAX(Summary!D23:E23) -> 0 | U22: =IF(T22=T23, TRUE, FALSE) -> TRUE | V22: =IF(U22=TRUE, FALSE, MAX(Summary!D23:E24)) -> FALSE | W22: {=IF(V22=FALSE, FALSE, ADDRESS(MAX(IF(Summary!D23:E24=V22,ROW(Summary!D23:E24))), MAX(IF(Summary!D23:E24=V22,COLUMN(Summary!D23:E24))), 4))} -> FALSE | X22: =IF(U22=TRUE, IF(Summary!E23=Summary!D23, TRUE, FALSE),FALSE) -> TRUE | Y22: =IF(X22=TRUE, "Desktop") -> Desktop | Z22: =IF(AND(Y22="Desktop", U22=TRUE), T22, FALSE) -> 0 | AA22: =IF(NOT(Z22=FALSE), Y22, IF(NOT(Z23=FALSE),Y23, FALSE)) -> Desktop | AB22: =IF(NOT(Z22=FALSE), Z22, IF(NOT(Z23=FALSE), Z23, V22)) -> 0 | AF22: =MIN(Summary!D23:E23) -> 0 | AG22: =IF(AF22=AF23, TRUE, FALSE) -> TRUE | AH22: =IF(AG22=TRUE, FALSE, MIN(Summary!D23:E24)) -> FALSE | AI22: {=IF(AH22=FALSE, FALSE, ADDRESS(MIN(IF(Summary!D23:E24=AH22,ROW(Summary!D23:E24))), MIN(IF(Summary!D23:E24=AH22,COLUMN(Summary!D23:E24))), 4))} -> FALSE | AJ22: =IF(AG22=TRUE, IF(Summary!D23=Summary!E23, TRUE, FALSE),FALSE) -> TRUE | AK22: =IF(AJ22=TRUE, "Desktop") -> Desktop | AL22: =IF(AND(AK22="Desktop", AG22=TRUE), AF22, FALSE) -> 0 | AM22: =IF(NOT(AL22=FALSE), AK22, IF(NOT(AL23=FALSE),AK23, FALSE)) -> Desktop | AN22: =IF(NOT(AL22=FALSE), AL22, IF(NOT(AL23=FALSE), AL23, AH22)) -> 0
I23: Cache: | J23: =IF(J22="Desktop",IF(Summary!D23=Summary!E23,"with and without cache",(IF(Summary!D23>Summary!E23,"with cache","without cache"))),IF(Summary!D24=Summary!E24,"with and without cache",(IF(Summary!D24>Summary!E24,"with cache","without cache")))) -> with and without cache | M23: =IF(M22="Desktop",IF(Summary!D23=Summary!E23,"with and without cache",IF(Summary!D23<Summary!E23,"with cache","without cache")),IF(Summary!D24=Summary!E24,"with and without cache",IF(Summary!D24<Summary!E24,"with cache","without cache"))) -> with and without cache | T23: =MAX(Summary!D24:E24) -> 0 | U23: =IF(T22=T23, TRUE, FALSE) -> TRUE | V23: =IF(U23=TRUE, FALSE, MAX(Summary!D24:E25)) -> FALSE | W23: {=IF(V23=FALSE, FALSE, ADDRESS(MAX(IF(Summary!D24:E25=V23,ROW(Summary!D24:E25))), MAX(IF(Summary!D24:E25=V23,COLUMN(Summary!D24:E25))), 4))} -> FALSE | X23: =IF(U23=TRUE, IF(Summary!E24=Summary!D24, TRUE, FALSE),FALSE) -> TRUE | Y23: =IF(X23=TRUE, "Mobile") -> Mobile | Z23: =IF(AND(Y23="Mobile", U23=TRUE), T23, FALSE) -> 0 | AF23: =MIN(Summary!D24:E24) -> 0 | AG23: =IF(AF22=AF23, TRUE, FALSE) -> TRUE | AH23: =IF(AG23=TRUE, FALSE, MIN(Summary!D24:E25)) -> FALSE | AI23: {=IF(AH23=FALSE, FALSE, ADDRESS(MIN(IF(Summary!D23:E24=AH23,ROW(Summary!D23:E24))), MIN(IF(Summary!D23:E24=AH23,COLUMN(Summary!D23:E24))), 4))} -> FALSE | AJ23: =IF(AG23=TRUE, IF(Summary!D24=Summary!E24, TRUE, FALSE),FALSE) -> TRUE | AK23: =IF(AJ23=TRUE, "Mobile") -> Mobile | AL23: =IF(AND(AK23="Mobile", AG23=TRUE), AF23, FALSE) -> 0
I25: =Summary!B27 -> 06_Sixth Link | J25: Best | K25: Performance Value | L25: Device Selector | M25: Worst | N25: Performance Value | O25: Device Selector | P25: Cell with Highest | Q25: Cell with Lowest | T25: Highest PS/Device | U25: isEqual? | V25: notEqual? Just get max number | W25: Loc | X25: w & w/ cache? | Y25: What device | Z25: HIGHEST SCORE | AA25: same device are false? | AB25: OVERALL HIGHEST PS | AF25: Lowest PS/Device | AG25: isEqual? | AH25: notEqual? Just get lowest number | AI25: Loc | AJ25: w & w/ cache? | AK25: What device | AL25: LOWEST SCORE | AM25: same device are false? | AN25: OVERALL LOWEST PS
I26: Device: | J26: {=IF(L26="Desktop", "Desktop", IF(L26="Mobile", "Mobile", INDIRECT(L26)))} -> Desktop | K26: =IF(AND(U26=TRUE, AB26=TRUE), AB26, MAX(Summary!D27:'Summary'!E28)) -> 0 | L26: =IF(NOT(AA26=FALSE), AA26, IF(LEFT(MID(P26,FIND("!",P26)+1,LEN(P26)),1)="D", LEFT(P26,FIND("!",P26)) & CHAR(CODE(LEFT(MID(P26,FIND("!",P26)+1,LEN(P26)),1))-1) & MID(P26,FIND("!",P26)+2,LEN(P26)), LEFT(P26,FIND("!",P26)) & CHAR(CODE(LEFT(MID(P26,FIND("!",P26)+1,LEN(P26)),1))-2) & MID(P26,FIND("!",P26)+2,LEN(P26)))) -> Desktop | M26: {=IF(O26="Desktop", "Desktop", IF(O26="Mobile", "Mobile", INDIRECT(O26)))} -> Desktop | N26: =IF(AND(AG26=TRUE, AN26=TRUE), AN26, MIN(Summary!D27:'Summary'!E28)) -> 0 | O26: =IF(NOT(AM26=FALSE), AM26, IF(LEFT(MID(Q26,FIND("!",Q26)+1,LEN(Q26)),1)="D", LEFT(Q26,FIND("!",Q26)) & CHAR(CODE(LEFT(MID(Q26,FIND("!",Q26)+1,LEN(Q26)),1))-1) & MID(Q26,FIND("!",Q26)+2,LEN(Q26)), LEFT(Q26,FIND("!",Q26)) & CHAR(CODE(LEFT(MID(Q26,FIND("!",Q26)+1,LEN(Q26)),1))-2) & MID(Q26,FIND("!",Q26)+2,LEN(Q26)))) -> Desktop | P26: {="Summary!" & ADDRESS(MIN(IF(Summary!D27:E28=K26,ROW(Summary!D27:E28))), MIN(IF(Summary!D27:E28=K26,COLUMN(Summary!D27:E28))), 4)} -> Summary!D27 | Q26: {="Summary!" & ADDRESS(MIN(IF(Summary!D27:E28=N26,ROW(Summary!D27:E28))), MIN(IF(Summary!D27:E28=N26,COLUMN(Summary!D27:E28))), 4)} -> Summary!D27 | T26: =MAX(Summary!D27:E27) -> 0 | U26: =IF(T26=T27, TRUE, FALSE) -> TRUE | V26: =IF(U26=TRUE, FALSE, MAX(Summary!D27:E28)) -> FALSE | W26: {=IF(V26=FALSE, FALSE, ADDRESS(MAX(IF(Summary!D27:E28=V26,ROW(Summary!D27:E28))), MAX(IF(Summary!D27:E28=V26,COLUMN(Summary!D27:E28))), 4))} -> FALSE | X26: =IF(U26=TRUE, IF(Summary!E27=Summary!D27, TRUE, FALSE),FALSE) -> TRUE | Y26: =IF(X26=TRUE, "Desktop") -> Desktop | Z26: =IF(AND(Y26="Desktop", U26=TRUE), T26, FALSE) -> 0 | AA26: =IF(NOT(Z26=FALSE), Y26, IF(NOT(Z27=FALSE),Y27, FALSE)) -> Desktop | AB26: =IF(NOT(Z26=FALSE), Z26, IF(NOT(Z27=FALSE), Z27, V26)) -> 0 | AF26: =MIN(Summary!D27:E27) -> 0 | AG26: =IF(AF26=AF27, TRUE, FALSE) -> TRUE | AH26: =IF(AG26=TRUE, FALSE, MIN(Summary!D27:E28)) -> FALSE | AI26: {=IF(AH26=FALSE, FALSE, ADDRESS(MIN(IF(Summary!D27:E28=AH26,ROW(Summary!D27:E28))), MIN(IF(Summary!D27:E28=AH26,COLUMN(Summary!D27:E28))), 4))} -> FALSE | AJ26: =IF(AG26=TRUE, IF(Summary!D27=Summary!E27, TRUE, FALSE),FALSE) -> TRUE | AK26: =IF(AJ26=TRUE, "Desktop") -> Desktop | AL26: =IF(AND(AK26="Desktop", AG26=TRUE), AF26, FALSE) -> 0 | AM26: =IF(NOT(AL26=FALSE), AK26, IF(NOT(AL27=FALSE),AK27, FALSE)) -> Desktop | AN26: =IF(NOT(AL26=FALSE), AL26, IF(NOT(AL27=FALSE), AL27, AH26)) -> 0
I27: Cache: | J27: =IF(J26="Desktop",IF(Summary!D27=Summary!E27,"with and without cache",(IF(Summary!D27>Summary!E27,"with cache","without cache"))),IF(Summary!D28=Summary!E28,"with and without cache",(IF(Summary!D28>Summary!E28,"with cache","without cache")))) -> with and without cache | M27: =IF(M26="Desktop",IF(Summary!D27=Summary!E27,"with and without cache",IF(Summary!D27<Summary!E27,"with cache","without cache")),IF(Summary!D28=Summary!E28,"with and without cache",IF(Summary!D28<Summary!E28,"with cache","without cache"))) -> with and without cache | T27: =MAX(Summary!D28:E28) -> 0 | U27: =IF(T26=T27, TRUE, FALSE) -> TRUE | V27: =IF(U27=TRUE, FALSE, MAX(Summary!D28:E29)) -> FALSE | W27: {=IF(V27=FALSE, FALSE, ADDRESS(MAX(IF(Summary!D28:E29=V27,ROW(Summary!D28:E29))), MAX(IF(Summary!D28:E29=V27,COLUMN(Summary!D28:E29))), 4))} -> FALSE | X27: =IF(U27=TRUE, IF(Summary!E28=Summary!D28, TRUE, FALSE),FALSE) -> TRUE | Y27: =IF(X27=TRUE, "Mobile") -> Mobile | Z27: =IF(AND(Y27="Mobile", U27=TRUE), T27, FALSE) -> 0 | AF27: =MIN(Summary!D28:E28) -> 0 | AG27: =IF(AF26=AF27, TRUE, FALSE) -> TRUE | AH27: =IF(AG27=TRUE, FALSE, MIN(Summary!D28:E29)) -> FALSE | AI27: {=IF(AH27=FALSE, FALSE, ADDRESS(MIN(IF(Summary!D27:E28=AH27,ROW(Summary!D27:E28))), MIN(IF(Summary!D27:E28=AH27,COLUMN(Summary!D27:E28))), 4))} -> FALSE | AJ27: =IF(AG27=TRUE, IF(Summary!D28=Summary!E28, TRUE, FALSE),FALSE) -> TRUE | AK27: =IF(AJ27=TRUE, "Mobile") -> Mobile | AL27: =IF(AND(AK27="Mobile", AG27=TRUE), AF27, FALSE) -> 0
I29: =Summary!B31 -> 07_Seventh Link | J29: Best | K29: Performance Value | L29: Device Selector | M29: Worst | N29: Performance Value | O29: Device Selector | P29: Cell with Highest | Q29: Cell with Lowest | T29: Highest PS/Device | U29: isEqual? | V29: notEqual? Just get max number | W29: Loc | X29: w & w/ cache? | Y29: What device | Z29: HIGHEST SCORE | AA29: same device are false? | AB29: OVERALL HIGHEST PS | AF29: Lowest PS/Device | AG29: isEqual? | AH29: notEqual? Just get lowest number | AI29: Loc | AJ29: w & w/ cache? | AK29: What device | AL29: LOWEST SCORE | AM29: same device are false? | AN29: OVERALL LOWEST PS
I30: Device: | J30: {=IF(L30="Desktop", "Desktop", IF(L30="Mobile", "Mobile", INDIRECT(L30)))} -> Desktop | K30: =IF(AND(U30=TRUE, AB30=TRUE), AB30, MAX(Summary!D31:'Summary'!E32)) -> 0 | L30: =IF(NOT(AA30=FALSE), AA30, IF(LEFT(MID(P30,FIND("!",P30)+1,LEN(P30)),1)="D", LEFT(P30,FIND("!",P30)) & CHAR(CODE(LEFT(MID(P30,FIND("!",P30)+1,LEN(P30)),1))-1) & MID(P30,FIND("!",P30)+2,LEN(P30)), LEFT(P30,FIND("!",P30)) & CHAR(CODE(LEFT(MID(P30,FIND("!",P30)+1,LEN(P30)),1))-2) & MID(P30,FIND("!",P30)+2,LEN(P30)))) -> Desktop | M30: {=IF(O30="Desktop", "Desktop", IF(O30="Mobile", "Mobile", INDIRECT(O30)))} -> Desktop | N30: =IF(AND(AG30=TRUE, AN30=TRUE), AN30, MIN(Summary!D31:'Summary'!E32)) -> 0 | O30: =IF(NOT(AM30=FALSE), AM30, IF(LEFT(MID(Q30,FIND("!",Q30)+1,LEN(Q30)),1)="D", LEFT(Q30,FIND("!",Q30)) & CHAR(CODE(LEFT(MID(Q30,FIND("!",Q30)+1,LEN(Q30)),1))-1) & MID(Q30,FIND("!",Q30)+2,LEN(Q30)), LEFT(Q30,FIND("!",Q30)) & CHAR(CODE(LEFT(MID(Q30,FIND("!",Q30)+1,LEN(Q30)),1))-2) & MID(Q30,FIND("!",Q30)+2,LEN(Q30)))) -> Desktop | P30: {="Summary!" & ADDRESS(MIN(IF(Summary!D31:E32=K30,ROW(Summary!D31:E32))), MIN(IF(Summary!D31:E32=K30,COLUMN(Summary!D31:E32))), 4)} -> Summary!D31 | Q30: {="Summary!" & ADDRESS(MIN(IF(Summary!D31:E32=N30,ROW(Summary!D31:E32))), MIN(IF(Summary!D31:E32=N30,COLUMN(Summary!D31:E32))), 4)} -> Summary!D31 | T30: =MAX(Summary!D31:E31) -> 0 | U30: =IF(T30=T31, TRUE, FALSE) -> TRUE | V30: =IF(U30=TRUE, FALSE, MAX(Summary!D31:E32)) -> FALSE | W30: {=IF(V30=FALSE, FALSE, ADDRESS(MAX(IF(Summary!D31:E32=V30,ROW(Summary!D31:E32))), MAX(IF(Summary!D31:E32=V30,COLUMN(Summary!D31:E32))), 4))} -> FALSE | X30: =IF(U30=TRUE, IF(Summary!E31=Summary!D31, TRUE, FALSE),FALSE) -> TRUE | Y30: =IF(X30=TRUE, "Desktop") -> Desktop | Z30: =IF(AND(Y30="Desktop", U30=TRUE), T30, FALSE) -> 0 | AA30: =IF(NOT(Z30=FALSE), Y30, IF(NOT(Z31=FALSE),Y31, FALSE)) -> Desktop | AB30: =IF(NOT(Z30=FALSE), Z30, IF(NOT(Z31=FALSE), Z31, V30)) -> 0 | AF30: =MIN(Summary!D31:E31) -> 0 | AG30: =IF(AF30=AF31, TRUE, FALSE) -> TRUE | AH30: =IF(AG30=TRUE, FALSE, MIN(Summary!D31:E32)) -> FALSE | AI30: {=IF(AH30=FALSE, FALSE, ADDRESS(MIN(IF(Summary!D31:E32=AH30,ROW(Summary!D31:E32))), MIN(IF(Summary!D31:E32=AH30,COLUMN(Summary!D31:E32))), 4))} -> FALSE | AJ30: =IF(AG30=TRUE, IF(Summary!D31=Summary!E31, TRUE, FALSE),FALSE) -> TRUE | AK30: =IF(AJ30=TRUE, "Desktop") -> Desktop | AL30: =IF(AND(AK30="Desktop", AG30=TRUE), AF30, FALSE) -> 0 | AM30: =IF(NOT(AL30=FALSE), AK30, IF(NOT(AL31=FALSE),AK31, FALSE)) -> Desktop | AN30: =IF(NOT(AL30=FALSE), AL30, IF(NOT(AL31=FALSE), AL31, AH30)) -> 0
I31: Cache: | J31: =IF(J30="Desktop",IF(Summary!D31=Summary!E31,"with and without cache",(IF(Summary!D31>Summary!E31,"with cache","without cache"))),IF(Summary!D32=Summary!E32,"with and without cache",(IF(Summary!D32>Summary!E32,"with cache","without cache")))) -> with and without cache | M31: =IF(M30="Desktop",IF(Summary!D31=Summary!E31,"with and without cache",IF(Summary!D31<Summary!E31,"with cache","without cache")),IF(Summary!D32=Summary!E32,"with and without cache",IF(Summary!D32<Summary!E32,"with cache","without cache"))) -> with and without cache | T31: =MAX(Summary!D32:E32) -> 0 | U31: =IF(T30=T31, TRUE, FALSE) -> TRUE | V31: =IF(U31=TRUE, FALSE, MAX(Summary!D32:E33)) -> FALSE | W31: {=IF(V31=FALSE, FALSE, ADDRESS(MAX(IF(Summary!D32:E33=V31,ROW(Summary!D32:E33))), MAX(IF(Summary!D32:E33=V31,COLUMN(Summary!D32:E33))), 4))} -> FALSE | X31: =IF(U31=TRUE, IF(Summary!E32=Summary!D32, TRUE, FALSE),FALSE) -> TRUE | Y31: =IF(X31=TRUE, "Mobile") -> Mobile | Z31: =IF(AND(Y31="Mobile", U31=TRUE), T31, FALSE) -> 0 | AF31: =MIN(Summary!D32:E32) -> 0 | AG31: =IF(AF30=AF31, TRUE, FALSE) -> TRUE | AH31: =IF(AG31=TRUE, FALSE, MIN(Summary!D32:E33)) -> FALSE | AI31: {=IF(AH31=FALSE, FALSE, ADDRESS(MIN(IF(Summary!D31:E32=AH31,ROW(Summary!D31:E32))), MIN(IF(Summary!D31:E32=AH31,COLUMN(Summary!D31:E32))), 4))} -> FALSE | AJ31: =IF(AG31=TRUE, IF(Summary!D32=Summary!E32, TRUE, FALSE),FALSE) -> TRUE | AK31: =IF(AJ31=TRUE, "Mobile") -> Mobile | AL31: =IF(AND(AK31="Mobile", AG31=TRUE), AF31, FALSE) -> 0
I33: =Summary!B35 -> 08_Eighth Link | J33: Best | K33: Performance Value | L33: Device Selector | M33: Worst | N33: Performance Value | O33: Device Selector | P33: Cell with Highest | Q33: Cell with Lowest | T33: Highest PS/Device | U33: isEqual? | V33: notEqual? Just get max number | W33: Loc | X33: w & w/ cache? | Y33: What device | Z33: HIGHEST SCORE | AA33: same device are false? | AB33: OVERALL HIGHEST PS | AF33: Lowest PS/Device | AG33: isEqual? | AH33: notEqual? Just get lowest number | AI33: Loc | AJ33: w & w/ cache? | AK33: What device | AL33: LOWEST SCORE | AM33: same device are false? | AN33: OVERALL LOWEST PS
I34: Device: | J34: {=IF(L34="Desktop", "Desktop", IF(L34="Mobile", "Mobile", INDIRECT(L34)))} -> Desktop | K34: =IF(AND(U34=TRUE, AB34=TRUE), AB34, MAX(Summary!D35:'Summary'!E36)) -> 0 | L34: =IF(NOT(AA34=FALSE), AA34, IF(LEFT(MID(P34,FIND("!",P34)+1,LEN(P34)),1)="D", LEFT(P34,FIND("!",P34)) & CHAR(CODE(LEFT(MID(P34,FIND("!",P34)+1,LEN(P34)),1))-1) & MID(P34,FIND("!",P34)+2,LEN(P34)), LEFT(P34,FIND("!",P34)) & CHAR(CODE(LEFT(MID(P34,FIND("!",P34)+1,LEN(P34)),1))-2) & MID(P34,FIND("!",P34)+2,LEN(P34)))) -> Desktop | M34: {=IF(O34="Desktop", "Desktop", IF(O34="Mobile", "Mobile", INDIRECT(O34)))} -> Desktop | N34: =IF(AND(AG34=TRUE, AN34=TRUE), AN34, MIN(Summary!D35:'Summary'!E36)) -> 0 | O34: =IF(NOT(AM34=FALSE), AM34, IF(LEFT(MID(Q34,FIND("!",Q34)+1,LEN(Q34)),1)="D", LEFT(Q34,FIND("!",Q34)) & CHAR(CODE(LEFT(MID(Q34,FIND("!",Q34)+1,LEN(Q34)),1))-1) & MID(Q34,FIND("!",Q34)+2,LEN(Q34)), LEFT(Q34,FIND("!",Q34)) & CHAR(CODE(LEFT(MID(Q34,FIND("!",Q34)+1,LEN(Q34)),1))-2) & MID(Q34,FIND("!",Q34)+2,LEN(Q34)))) -> Desktop | P34: {="Summary!" & ADDRESS(MIN(IF(Summary!D35:E36=K34,ROW(Summary!D35:E36))), MIN(IF(Summary!D35:E36=K34,COLUMN(Summary!D35:E36))), 4)} -> Summary!D35 | Q34: {="Summary!" & ADDRESS(MIN(IF(Summary!D35:E36=N34,ROW(Summary!D35:E36))), MIN(IF(Summary!D35:E36=N34,COLUMN(Summary!D35:E36))), 4)} -> Summary!D35 | T34: =MAX(Summary!D35:E35) -> 0 | U34: =IF(T34=T35, TRUE, FALSE) -> TRUE | V34: =IF(U34=TRUE, FALSE, MAX(Summary!D35:E36)) -> FALSE | W34: {=IF(V34=FALSE, FALSE, ADDRESS(MAX(IF(Summary!D35:E36=V34,ROW(Summary!D35:E36))), MAX(IF(Summary!D35:E36=V34,COLUMN(Summary!D35:E36))), 4))} -> FALSE | X34: =IF(U34=TRUE, IF(Summary!E35=Summary!D35, TRUE, FALSE),FALSE) -> TRUE | Y34: =IF(X34=TRUE, "Desktop") -> Desktop | Z34: =IF(AND(Y34="Desktop", U34=TRUE), T34, FALSE) -> 0 | AA34: =IF(NOT(Z34=FALSE), Y34, IF(NOT(Z35=FALSE),Y35, FALSE)) -> Desktop | AB34: =IF(NOT(Z34=FALSE), Z34, IF(NOT(Z35=FALSE), Z35, V34)) -> 0 | AF34: =MIN(Summary!D35:E35) -> 0 | AG34: =IF(AF34=AF35, TRUE, FALSE) -> TRUE | AH34: =IF(AG34=TRUE, FALSE, MIN(Summary!D35:E36)) -> FALSE | AI34: {=IF(AH34=FALSE, FALSE, ADDRESS(MIN(IF(Summary!D35:E36=AH34,ROW(Summary!D35:E36))), MIN(IF(Summary!D35:E36=AH34,COLUMN(Summary!D35:E36))), 4))} -> FALSE | AJ34: =IF(AG34=TRUE, IF(Summary!D35=Summary!E35, TRUE, FALSE),FALSE) -> TRUE | AK34: =IF(AJ34=TRUE, "Desktop") -> Desktop | AL34: =IF(AND(AK34="Desktop", AG34=TRUE), AF34, FALSE) -> 0 | AM34: =IF(NOT(AL34=FALSE), AK34, IF(NOT(AL35=FALSE),AK35, FALSE)) -> Desktop | AN34: =IF(NOT(AL34=FALSE), AL34, IF(NOT(AL35=FALSE), AL35, AH34)) -> 0
I35: Cache: | J35: =IF(J34="Desktop",IF(Summary!D35=Summary!E35,"with and without cache",(IF(Summary!D35>Summary!E35,"with cache","without cache"))),IF(Summary!D36=Summary!E36,"with and without cache",(IF(Summary!D36>Summary!E36,"with cache","without cache")))) -> with and without cache | M35: =IF(M34="Desktop",IF(Summary!D35=Summary!E35,"with and without cache",IF(Summary!D35<Summary!E35,"with cache","without cache")),IF(Summary!D36=Summary!E36,"with and without cache",IF(Summary!D36<Summary!E36,"with cache","without cache"))) -> with and without cache | T35: =MAX(Summary!D36:E36) -> 0 | U35: =IF(T34=T35, TRUE, FALSE) -> TRUE | V35: =IF(U35=TRUE, FALSE, MAX(Summary!D36:E37)) -> FALSE | W35: {=IF(V35=FALSE, FALSE, ADDRESS(MAX(IF(Summary!D36:E37=V35,ROW(Summary!D36:E37))), MAX(IF(Summary!D36:E37=V35,COLUMN(Summary!D36:E37))), 4))} -> FALSE | X35: =IF(U35=TRUE, IF(Summary!E36=Summary!D36, TRUE, FALSE),FALSE) -> TRUE | Y35: =IF(X35=TRUE, "Mobile") -> Mobile | Z35: =IF(AND(Y35="Mobile", U35=TRUE), T35, FALSE) -> 0 | AF35: =MIN(Summary!D36:E36) -> 0 | AG35: =IF(AF34=AF35, TRUE, FALSE) -> TRUE | AH35: =IF(AG35=TRUE, FALSE, MIN(Summary!D36:E37)) -> FALSE | AI35: {=IF(AH35=FALSE, FALSE, ADDRESS(MIN(IF(Summary!D35:E36=AH35,ROW(Summary!D35:E36))), MIN(IF(Summary!D35:E36=AH35,COLUMN(Summary!D35:E36))), 4))} -> FALSE | AJ35: =IF(AG35=TRUE, IF(Summary!D36=Summary!E36, TRUE, FALSE),FALSE) -> TRUE | AK35: =IF(AJ35=TRUE, "Mobile") -> Mobile | AL35: =IF(AND(AK35="Mobile", AG35=TRUE), AF35, FALSE) -> 0
T37: With and without Cache | AF37: With and without Cache
I38: Name | J38: Best | K38: Worst | T38: Highest PS | U38: Loc | V38: Highest PS All Page | W38: Highest PS Loc | X38: Referenced Loc | Y38: Sheet | Z38: Sheets | AA38: Page | AB38: Pages | AC38: Device | AD38: Cache | AF38: Lowest PS | AG38: Loc | AH38: Lowest PS All Page | AI38: Lowest PS Loc | AJ38: Referenced Loc | AK38: Sheet | AL38: Sheets | AM38: Page | AN38: Pages | AO38: Device | AP38: Cache
I39: Record performance value: | J39: =MAX(K6,N6,K10,N10,K14,N14,K18,N18,K18,K22,N22,K26,N26,K30,N30,K34,N34) -> 0 | K39: =MIN(K6,N6,K10,N10,K14,N14,K18,N18,K18,K22,N22,K26,N26,K30,N30,K34,N34) -> 0 | T39: =IF(J7="with and without cache", K6, -1) -> 0 | U39: K6 | V39: {=_xlfn._xlws.FILTER(T39:T46, T39:T46=MAX(T39:T46))} -> 0 | W39: {=_xlfn._xlws.FILTER(ADDRESS(ROW(T39:T46), COLUMN(T39:T46), 4), T39:T46=MAX(T39:T46))} -> T39 | X39: {=_xlfn._xlws.FILTER(U39:U46, T39:T46=MAX(T39:T46))} -> K6 | Y39: {=_xlfn.MAP(_xlfn.ANCHORARRAY(X39), _xlfn.LAMBDA(_xlpm.cell_address, INDIRECT(ADDRESS(ROW(INDIRECT(_xlpm.cell_address))-1, COLUMN(INDIRECT(_xlpm.cell_address))-2))))} -> 01_First Link | Z39: {=_xlfn.TEXTJOIN(", ", TRUE,_xlfn.ANCHORARRAY( Y39))} -> 01_First Link | AA39: {=_xlfn.MAP(_xlfn.ANCHORARRAY(X39), _xlfn.LAMBDA(_xlpm.cell_address, MID(INDIRECT(ADDRESS(ROW(INDIRECT(_xlpm.cell_address))-1, COLUMN(INDIRECT(_xlpm.cell_address))-2)), FIND("_", INDIRECT(ADDRESS(ROW(INDIRECT(_xlpm.cell_address))-1, COLUMN(INDIRECT(_xlpm.cell_address))-2)))+1, 999)))} -> First Link | AB39: {=_xlfn.TEXTJOIN(", ", TRUE,_xlfn.ANCHORARRAY( AA39))} -> First Link | AC39: {=_xlfn.MAP(_xlfn.ANCHORARRAY(X39), _xlfn.LAMBDA(_xlpm.cell_address, INDIRECT(ADDRESS(ROW(INDIRECT(_xlpm.cell_address)), COLUMN(INDIRECT(_xlpm.cell_address))-1))))} -> Desktop | AD39: {=_xlfn.MAP(_xlfn.ANCHORARRAY(X39), _xlfn.LAMBDA(_xlpm.cell_address, INDIRECT(ADDRESS(ROW(INDIRECT(_xlpm.cell_address))+1, COLUMN(INDIRECT(_xlpm.cell_address))-1))))} -> with and without cache | AF39: =IF(M7="with and without cache", N6, 99999) -> 0 | AG39: N6 | AH39: {=_xlfn._xlws.FILTER(AF39:AF46, AF39:AF46=MIN(AF39:AF46))} -> 0 | AI39: {=_xlfn._xlws.FILTER(ADDRESS(ROW(AF39:AF46), COLUMN(AF39:AF46), 4), AF39:AF46=MIN(AF39:AF46))} -> AF39 | AJ39: {=_xlfn._xlws.FILTER(AG39:AG46, AF39:AF46=MIN(AF39:AF46))} -> N6 | AK39: {=_xlfn.MAP(_xlfn.ANCHORARRAY(AJ39), _xlfn.LAMBDA(_xlpm.cell_address, INDIRECT(ADDRESS(ROW(INDIRECT(_xlpm.cell_address))-1, COLUMN(INDIRECT(_xlpm.cell_address))-5))))} -> 01_First Link | AL39: {=_xlfn.TEXTJOIN(", ", TRUE,_xlfn.ANCHORARRAY( AK39))} -> 01_First Link | AM39: {=_xlfn.MAP(_xlfn.ANCHORARRAY(AJ39),_xlfn.LAMBDA(_xlpm.cell_address,MID(INDIRECT(ADDRESS(ROW(INDIRECT(_xlpm.cell_address))-1,COLUMN(INDIRECT(_xlpm.cell_address))-5)),FIND("_",INDIRECT(ADDRESS(ROW(INDIRECT(_xlpm.cell_address))-1,COLUMN(INDIRECT(_xlpm.cell_address))-5)))+1,999)))} -> First Link | AN39: {=_xlfn.TEXTJOIN(", ", TRUE,_xlfn.ANCHORARRAY( AM39))} -> First Link | AO39: {=_xlfn.MAP(_xlfn.ANCHORARRAY(AJ39), _xlfn.LAMBDA(_xlpm.cell_address, INDIRECT(ADDRESS(ROW(INDIRECT(_xlpm.cell_address)), COLUMN(INDIRECT(_xlpm.cell_address))-1))))} -> Desktop | AP39: {=_xlfn.MAP(_xlfn.ANCHORARRAY(AJ39), _xlfn.LAMBDA(_xlpm.cell_address, INDIRECT(ADDRESS(ROW(INDIRECT(_xlpm.cell_address))+1, COLUMN(INDIRECT(_xlpm.cell_address))-1))))} -> with and without cache
I40: Record performance value location: | J40: {=ADDRESS(MIN(IF(Summary!D7:E36=J39,ROW(Summary!D7:E36))), MIN(IF(Summary!D7:E36=J39,COLUMN(Summary!D7:E36))), 4)} -> D7 | K40: {=ADDRESS(MIN(IF(Summary!D7:E36=K39,ROW(Summary!D7:E36))), MIN(IF(Summary!D7:E36=K39,COLUMN(Summary!D7:E36))), 4)} -> D7 | T40: =IF(J11="with and without cache", K10, FALSE) -> 0 | U40: K10 | AF40: =IF(M11="with and without cache", N10, FALSE) -> 0 | AG40: N10
I41: With and Without Cache Value Location: | J41: ="Summary!" & IF(Formula_Sheet!U6, CHAR(CODE(LEFT(J40,1)) + 1)&MID(J40,2,99), CHAR(CODE(LEFT(J40,1)) + 1)&MID(J40,2,99)) -> Summary!E7 | K41: ="Summary!" & IF(LEFT(K40,1)="D", CHAR(CODE(LEFT(K40,1)) + 1)&MID(K40,2,99), K40) -> Summary!E7 | T41: =IF(J15="with and without cache", K14, FALSE) -> 0 | U41: K14 | AF41: =IF(M15="with and without cache", N14, FALSE) -> 0 | AG41: N14
I42: Cache Value: | J42: {=IF(LEFT(J40,1)="D", IF(J39=INDIRECT(J41), "with and without cache", "with cache"), IF(LEFT(J40,1)="E", "without cache", "Incorrect cache location" ) )} -> with and without cache | K42: {=IF(LEFT(K40,1)="D", IF(K39=INDIRECT(K41), "with and without cache", "with cache"), IF(LEFT(K40,1)="E", "without cache", "Incorrect cache location" ) )} -> with and without cache | T42: =IF(J19="with and without cache", K18, FALSE) -> 0 | U42: K18 | AF42: =IF(M19="with and without cache", N18, FALSE) -> 0 | AG42: N18
